ERROR:root:get_media_id_by_tag
Traceback (most recent call last):
  File "C:\Users\Administrator\AppData\Local\Programs\Python\Python37-32\lib\site-packages\urllib3\connectionpool.py", line 600, in urlopen
    chunked=chunked)
  File "C:\Users\Administrator\AppData\Local\Programs\Python\Python37-32\lib\site-packages\urllib3\connectionpool.py", line 384, in _make_request
    six.raise_from(e, None)
  File "<string>", line 2, in raise_from
  File "C:\Users\Administrator\AppData\Local\Programs\Python\Python37-32\lib\site-packages\urllib3\connectionpool.py", line 380, in _make_request
    httplib_response = conn.getresponse()
  File "C:\Users\Administrator\AppData\Local\Programs\Python\Python37-32\lib\http\client.py", line 1321, in getresponse
    response.begin()
  File "C:\Users\Administrator\AppData\Local\Programs\Python\Python37-32\lib\http\client.py", line 320, in begin
    self.headers = self.msg = parse_headers(self.fp)
  File "C:\Users\Administrator\AppData\Local\Programs\Python\Python37-32\lib\http\client.py", line 205, in parse_headers
    line = fp.readline(_MAXLINE + 1)
  File "C:\Users\Administrator\AppData\Local\Programs\Python\Python37-32\lib\socket.py", line 589, in readinto
    return self._sock.recv_into(b)
  File "C:\Users\Administrator\AppData\Local\Programs\Python\Python37-32\lib\ssl.py", line 1052, in recv_into
    return self.read(nbytes, buffer)
  File "C:\Users\Administrator\AppData\Local\Programs\Python\Python37-32\lib\ssl.py", line 911, in read
    return self._sslobj.read(len, buffer)
ConnectionResetError: [WinError 10054] An existing connection was forcibly closed by the remote host

During handling of the above exception, another exception occurred:

Traceback (most recent call last):
  File "C:\Users\Administrator\AppData\Local\Programs\Python\Python37-32\lib\site-packages\requests\adapters.py", line 449, in send
    timeout=timeout
  File "C:\Users\Administrator\AppData\Local\Programs\Python\Python37-32\lib\site-packages\urllib3\connectionpool.py", line 638, in urlopen
    _stacktrace=sys.exc_info()[2])
  File "C:\Users\Administrator\AppData\Local\Programs\Python\Python37-32\lib\site-packages\urllib3\util\retry.py", line 367, in increment
    raise six.reraise(type(error), error, _stacktrace)
  File "C:\Users\Administrator\AppData\Local\Programs\Python\Python37-32\lib\site-packages\urllib3\packages\six.py", line 685, in reraise
    raise value.with_traceback(tb)
  File "C:\Users\Administrator\AppData\Local\Programs\Python\Python37-32\lib\site-packages\urllib3\connectionpool.py", line 600, in urlopen
    chunked=chunked)
  File "C:\Users\Administrator\AppData\Local\Programs\Python\Python37-32\lib\site-packages\urllib3\connectionpool.py", line 384, in _make_request
    six.raise_from(e, None)
  File "<string>", line 2, in raise_from
  File "C:\Users\Administrator\AppData\Local\Programs\Python\Python37-32\lib\site-packages\urllib3\connectionpool.py", line 380, in _make_request
    httplib_response = conn.getresponse()
  File "C:\Users\Administrator\AppData\Local\Programs\Python\Python37-32\lib\http\client.py", line 1321, in getresponse
    response.begin()
  File "C:\Users\Administrator\AppData\Local\Programs\Python\Python37-32\lib\http\client.py", line 320, in begin
    self.headers = self.msg = parse_headers(self.fp)
  File "C:\Users\Administrator\AppData\Local\Programs\Python\Python37-32\lib\http\client.py", line 205, in parse_headers
    line = fp.readline(_MAXLINE + 1)
  File "C:\Users\Administrator\AppData\Local\Programs\Python\Python37-32\lib\socket.py", line 589, in readinto
    return self._sock.recv_into(b)
  File "C:\Users\Administrator\AppData\Local\Programs\Python\Python37-32\lib\ssl.py", line 1052, in recv_into
    return self.read(nbytes, buffer)
  File "C:\Users\Administrator\AppData\Local\Programs\Python\Python37-32\lib\ssl.py", line 911, in read
    return self._sslobj.read(len, buffer)
urllib3.exceptions.ProtocolError: ('Connection aborted.', ConnectionResetError(10054, 'An existing connection was forcibly closed by the remote host', None, 10054, None))

During handling of the above exception, another exception occurred:

Traceback (most recent call last):
  File "C:\Users\Administrator\Desktop\instabot.py-master\instabot_py\instabot.py", line 685, in get_media_id_by_tag
    r = self.s.get(url_tag)
  File "C:\Users\Administrator\AppData\Local\Programs\Python\Python37-32\lib\site-packages\requests\sessions.py", line 546, in get
    return self.request('GET', url, **kwargs)
  File "C:\Users\Administrator\AppData\Local\Programs\Python\Python37-32\lib\site-packages\requests\sessions.py", line 533, in request
    resp = self.send(prep, **send_kwargs)
  File "C:\Users\Administrator\AppData\Local\Programs\Python\Python37-32\lib\site-packages\requests\sessions.py", line 646, in send
    r = adapter.send(request, **kwargs)
  File "C:\Users\Administrator\AppData\Local\Programs\Python\Python37-32\lib\site-packages\requests\adapters.py", line 498, in send
    raise ConnectionError(err, request=request)
requests.exceptions.ConnectionError: ('Connection aborted.', ConnectionResetError(10054, 'An existing connection was forcibly closed by the remote host', None, 10054, None))
ERROR:root:get_media_id_by_tag
Traceback (most recent call last):
  File "C:\Users\Administrator\AppData\Local\Programs\Python\Python37-32\lib\site-packages\urllib3\connectionpool.py", line 600, in urlopen
    chunked=chunked)
  File "C:\Users\Administrator\AppData\Local\Programs\Python\Python37-32\lib\site-packages\urllib3\connectionpool.py", line 384, in _make_request
    six.raise_from(e, None)
  File "<string>", line 2, in raise_from
  File "C:\Users\Administrator\AppData\Local\Programs\Python\Python37-32\lib\site-packages\urllib3\connectionpool.py", line 380, in _make_request
    httplib_response = conn.getresponse()
  File "C:\Users\Administrator\AppData\Local\Programs\Python\Python37-32\lib\http\client.py", line 1321, in getresponse
    response.begin()
  File "C:\Users\Administrator\AppData\Local\Programs\Python\Python37-32\lib\http\client.py", line 320, in begin
    self.headers = self.msg = parse_headers(self.fp)
  File "C:\Users\Administrator\AppData\Local\Programs\Python\Python37-32\lib\http\client.py", line 205, in parse_headers
    line = fp.readline(_MAXLINE + 1)
  File "C:\Users\Administrator\AppData\Local\Programs\Python\Python37-32\lib\socket.py", line 589, in readinto
    return self._sock.recv_into(b)
  File "C:\Users\Administrator\AppData\Local\Programs\Python\Python37-32\lib\ssl.py", line 1052, in recv_into
    return self.read(nbytes, buffer)
  File "C:\Users\Administrator\AppData\Local\Programs\Python\Python37-32\lib\ssl.py", line 911, in read
    return self._sslobj.read(len, buffer)
ConnectionResetError: [WinError 10054] An existing connection was forcibly closed by the remote host

During handling of the above exception, another exception occurred:

Traceback (most recent call last):
  File "C:\Users\Administrator\AppData\Local\Programs\Python\Python37-32\lib\site-packages\requests\adapters.py", line 449, in send
    timeout=timeout
  File "C:\Users\Administrator\AppData\Local\Programs\Python\Python37-32\lib\site-packages\urllib3\connectionpool.py", line 638, in urlopen
    _stacktrace=sys.exc_info()[2])
  File "C:\Users\Administrator\AppData\Local\Programs\Python\Python37-32\lib\site-packages\urllib3\util\retry.py", line 367, in increment
    raise six.reraise(type(error), error, _stacktrace)
  File "C:\Users\Administrator\AppData\Local\Programs\Python\Python37-32\lib\site-packages\urllib3\packages\six.py", line 685, in reraise
    raise value.with_traceback(tb)
  File "C:\Users\Administrator\AppData\Local\Programs\Python\Python37-32\lib\site-packages\urllib3\connectionpool.py", line 600, in urlopen
    chunked=chunked)
  File "C:\Users\Administrator\AppData\Local\Programs\Python\Python37-32\lib\site-packages\urllib3\connectionpool.py", line 384, in _make_request
    six.raise_from(e, None)
  File "<string>", line 2, in raise_from
  File "C:\Users\Administrator\AppData\Local\Programs\Python\Python37-32\lib\site-packages\urllib3\connectionpool.py", line 380, in _make_request
    httplib_response = conn.getresponse()
  File "C:\Users\Administrator\AppData\Local\Programs\Python\Python37-32\lib\http\client.py", line 1321, in getresponse
    response.begin()
  File "C:\Users\Administrator\AppData\Local\Programs\Python\Python37-32\lib\http\client.py", line 320, in begin
    self.headers = self.msg = parse_headers(self.fp)
  File "C:\Users\Administrator\AppData\Local\Programs\Python\Python37-32\lib\http\client.py", line 205, in parse_headers
    line = fp.readline(_MAXLINE + 1)
  File "C:\Users\Administrator\AppData\Local\Programs\Python\Python37-32\lib\socket.py", line 589, in readinto
    return self._sock.recv_into(b)
  File "C:\Users\Administrator\AppData\Local\Programs\Python\Python37-32\lib\ssl.py", line 1052, in recv_into
    return self.read(nbytes, buffer)
  File "C:\Users\Administrator\AppData\Local\Programs\Python\Python37-32\lib\ssl.py", line 911, in read
    return self._sslobj.read(len, buffer)
urllib3.exceptions.ProtocolError: ('Connection aborted.', ConnectionResetError(10054, 'An existing connection was forcibly closed by the remote host', None, 10054, None))

During handling of the above exception, another exception occurred:

Traceback (most recent call last):
  File "C:\Users\Administrator\Desktop\instabot.py-master\instabot_py\instabot.py", line 685, in get_media_id_by_tag
    r = self.s.get(url_tag)
  File "C:\Users\Administrator\AppData\Local\Programs\Python\Python37-32\lib\site-packages\requests\sessions.py", line 546, in get
    return self.request('GET', url, **kwargs)
  File "C:\Users\Administrator\AppData\Local\Programs\Python\Python37-32\lib\site-packages\requests\sessions.py", line 533, in request
    resp = self.send(prep, **send_kwargs)
  File "C:\Users\Administrator\AppData\Local\Programs\Python\Python37-32\lib\site-packages\requests\sessions.py", line 646, in send
    r = adapter.send(request, **kwargs)
  File "C:\Users\Administrator\AppData\Local\Programs\Python\Python37-32\lib\site-packages\requests\adapters.py", line 498, in send
    raise ConnectionError(err, request=request)
requests.exceptions.ConnectionError: ('Connection aborted.', ConnectionResetError(10054, 'An existing connection was forcibly closed by the remote host', None, 10054, None))
ERROR:root:get_media_id_recent_feed
Traceback (most recent call last):
  File "C:\Users\Administrator\AppData\Local\Programs\Python\Python37-32\lib\site-packages\urllib3\response.py", line 360, in _error_catcher
    yield
  File "C:\Users\Administrator\AppData\Local\Programs\Python\Python37-32\lib\site-packages\urllib3\response.py", line 666, in read_chunked
    self._update_chunk_length()
  File "C:\Users\Administrator\AppData\Local\Programs\Python\Python37-32\lib\site-packages\urllib3\response.py", line 598, in _update_chunk_length
    line = self._fp.fp.readline()
  File "C:\Users\Administrator\AppData\Local\Programs\Python\Python37-32\lib\socket.py", line 589, in readinto
    return self._sock.recv_into(b)
  File "C:\Users\Administrator\AppData\Local\Programs\Python\Python37-32\lib\ssl.py", line 1052, in recv_into
    return self.read(nbytes, buffer)
  File "C:\Users\Administrator\AppData\Local\Programs\Python\Python37-32\lib\ssl.py", line 911, in read
    return self._sslobj.read(len, buffer)
ConnectionResetError: [WinError 10054] An existing connection was forcibly closed by the remote host

During handling of the above exception, another exception occurred:

Traceback (most recent call last):
  File "C:\Users\Administrator\AppData\Local\Programs\Python\Python37-32\lib\site-packages\requests\models.py", line 750, in generate
    for chunk in self.raw.stream(chunk_size, decode_content=True):
  File "C:\Users\Administrator\AppData\Local\Programs\Python\Python37-32\lib\site-packages\urllib3\response.py", line 490, in stream
    for line in self.read_chunked(amt, decode_content=decode_content):
  File "C:\Users\Administrator\AppData\Local\Programs\Python\Python37-32\lib\site-packages\urllib3\response.py", line 694, in read_chunked
    self._original_response.close()
  File "C:\Users\Administrator\AppData\Local\Programs\Python\Python37-32\lib\contextlib.py", line 130, in __exit__
    self.gen.throw(type, value, traceback)
  File "C:\Users\Administrator\AppData\Local\Programs\Python\Python37-32\lib\site-packages\urllib3\response.py", line 378, in _error_catcher
    raise ProtocolError('Connection broken: %r' % e, e)
urllib3.exceptions.ProtocolError: ("Connection broken: ConnectionResetError(10054, 'An existing connection was forcibly closed by the remote host', None, 10054, None)", ConnectionResetError(10054, 'An existing connection was forcibly closed by the remote host', None, 10054, None))

During handling of the above exception, another exception occurred:

Traceback (most recent call last):
  File "C:\Users\Administrator\Desktop\instabot.py-master\instabot_py\instabot.py", line 1631, in get_media_id_recent_feed
    r = self.s.get(url_tag)
  File "C:\Users\Administrator\AppData\Local\Programs\Python\Python37-32\lib\site-packages\requests\sessions.py", line 546, in get
    return self.request('GET', url, **kwargs)
  File "C:\Users\Administrator\AppData\Local\Programs\Python\Python37-32\lib\site-packages\requests\sessions.py", line 533, in request
    resp = self.send(prep, **send_kwargs)
  File "C:\Users\Administrator\AppData\Local\Programs\Python\Python37-32\lib\site-packages\requests\sessions.py", line 686, in send
    r.content
  File "C:\Users\Administrator\AppData\Local\Programs\Python\Python37-32\lib\site-packages\requests\models.py", line 828, in content
    self._content = b''.join(self.iter_content(CONTENT_CHUNK_SIZE)) or b''
  File "C:\Users\Administrator\AppData\Local\Programs\Python\Python37-32\lib\site-packages\requests\models.py", line 753, in generate
    raise ChunkedEncodingError(e)
requests.exceptions.ChunkedEncodingError: ("Connection broken: ConnectionResetError(10054, 'An existing connection was forcibly closed by the remote host', None, 10054, None)", ConnectionResetError(10054, 'An existing connection was forcibly closed by the remote host', None, 10054, None))
ERROR:root:get_media_id_by_tag
Traceback (most recent call last):
  File "C:\Users\Administrator\AppData\Local\Programs\Python\Python37-32\lib\site-packages\urllib3\response.py", line 360, in _error_catcher
    yield
  File "C:\Users\Administrator\AppData\Local\Programs\Python\Python37-32\lib\site-packages\urllib3\response.py", line 442, in read
    data = self._fp.read(amt)
  File "C:\Users\Administrator\AppData\Local\Programs\Python\Python37-32\lib\http\client.py", line 447, in read
    n = self.readinto(b)
  File "C:\Users\Administrator\AppData\Local\Programs\Python\Python37-32\lib\http\client.py", line 491, in readinto
    n = self.fp.readinto(b)
  File "C:\Users\Administrator\AppData\Local\Programs\Python\Python37-32\lib\socket.py", line 589, in readinto
    return self._sock.recv_into(b)
  File "C:\Users\Administrator\AppData\Local\Programs\Python\Python37-32\lib\ssl.py", line 1052, in recv_into
    return self.read(nbytes, buffer)
  File "C:\Users\Administrator\AppData\Local\Programs\Python\Python37-32\lib\ssl.py", line 911, in read
    return self._sslobj.read(len, buffer)
ConnectionResetError: [WinError 10054] An existing connection was forcibly closed by the remote host

During handling of the above exception, another exception occurred:

Traceback (most recent call last):
  File "C:\Users\Administrator\AppData\Local\Programs\Python\Python37-32\lib\site-packages\requests\models.py", line 750, in generate
    for chunk in self.raw.stream(chunk_size, decode_content=True):
  File "C:\Users\Administrator\AppData\Local\Programs\Python\Python37-32\lib\site-packages\urllib3\response.py", line 494, in stream
    data = self.read(amt=amt, decode_content=decode_content)
  File "C:\Users\Administrator\AppData\Local\Programs\Python\Python37-32\lib\site-packages\urllib3\response.py", line 459, in read
    raise IncompleteRead(self._fp_bytes_read, self.length_remaining)
  File "C:\Users\Administrator\AppData\Local\Programs\Python\Python37-32\lib\contextlib.py", line 130, in __exit__
    self.gen.throw(type, value, traceback)
  File "C:\Users\Administrator\AppData\Local\Programs\Python\Python37-32\lib\site-packages\urllib3\response.py", line 378, in _error_catcher
    raise ProtocolError('Connection broken: %r' % e, e)
urllib3.exceptions.ProtocolError: ("Connection broken: ConnectionResetError(10054, 'An existing connection was forcibly closed by the remote host', None, 10054, None)", ConnectionResetError(10054, 'An existing connection was forcibly closed by the remote host', None, 10054, None))

During handling of the above exception, another exception occurred:

Traceback (most recent call last):
  File "C:\Users\Administrator\Desktop\instabot.py-master\instabot_py\instabot.py", line 685, in get_media_id_by_tag
    r = self.s.get(url_tag)
  File "C:\Users\Administrator\AppData\Local\Programs\Python\Python37-32\lib\site-packages\requests\sessions.py", line 546, in get
    return self.request('GET', url, **kwargs)
  File "C:\Users\Administrator\AppData\Local\Programs\Python\Python37-32\lib\site-packages\requests\sessions.py", line 533, in request
    resp = self.send(prep, **send_kwargs)
  File "C:\Users\Administrator\AppData\Local\Programs\Python\Python37-32\lib\site-packages\requests\sessions.py", line 686, in send
    r.content
  File "C:\Users\Administrator\AppData\Local\Programs\Python\Python37-32\lib\site-packages\requests\models.py", line 828, in content
    self._content = b''.join(self.iter_content(CONTENT_CHUNK_SIZE)) or b''
  File "C:\Users\Administrator\AppData\Local\Programs\Python\Python37-32\lib\site-packages\requests\models.py", line 753, in generate
    raise ChunkedEncodingError(e)
requests.exceptions.ChunkedEncodingError: ("Connection broken: ConnectionResetError(10054, 'An existing connection was forcibly closed by the remote host', None, 10054, None)", ConnectionResetError(10054, 'An existing connection was forcibly closed by the remote host', None, 10054, None))
ERROR:root:get_media_id_recent_feed
Traceback (most recent call last):
  File "C:\Users\Administrator\AppData\Local\Programs\Python\Python37-32\lib\site-packages\urllib3\response.py", line 360, in _error_catcher
    yield
  File "C:\Users\Administrator\AppData\Local\Programs\Python\Python37-32\lib\site-packages\urllib3\response.py", line 669, in read_chunked
    chunk = self._handle_chunk(amt)
  File "C:\Users\Administrator\AppData\Local\Programs\Python\Python37-32\lib\site-packages\urllib3\response.py", line 615, in _handle_chunk
    value = self._fp._safe_read(amt)
  File "C:\Users\Administrator\AppData\Local\Programs\Python\Python37-32\lib\http\client.py", line 610, in _safe_read
    chunk = self.fp.read(min(amt, MAXAMOUNT))
  File "C:\Users\Administrator\AppData\Local\Programs\Python\Python37-32\lib\socket.py", line 589, in readinto
    return self._sock.recv_into(b)
  File "C:\Users\Administrator\AppData\Local\Programs\Python\Python37-32\lib\ssl.py", line 1052, in recv_into
    return self.read(nbytes, buffer)
  File "C:\Users\Administrator\AppData\Local\Programs\Python\Python37-32\lib\ssl.py", line 911, in read
    return self._sslobj.read(len, buffer)
ConnectionResetError: [WinError 10054] An existing connection was forcibly closed by the remote host

During handling of the above exception, another exception occurred:

Traceback (most recent call last):
  File "C:\Users\Administrator\AppData\Local\Programs\Python\Python37-32\lib\site-packages\requests\models.py", line 750, in generate
    for chunk in self.raw.stream(chunk_size, decode_content=True):
  File "C:\Users\Administrator\AppData\Local\Programs\Python\Python37-32\lib\site-packages\urllib3\response.py", line 490, in stream
    for line in self.read_chunked(amt, decode_content=decode_content):
  File "C:\Users\Administrator\AppData\Local\Programs\Python\Python37-32\lib\site-packages\urllib3\response.py", line 694, in read_chunked
    self._original_response.close()
  File "C:\Users\Administrator\AppData\Local\Programs\Python\Python37-32\lib\contextlib.py", line 130, in __exit__
    self.gen.throw(type, value, traceback)
  File "C:\Users\Administrator\AppData\Local\Programs\Python\Python37-32\lib\site-packages\urllib3\response.py", line 378, in _error_catcher
    raise ProtocolError('Connection broken: %r' % e, e)
urllib3.exceptions.ProtocolError: ("Connection broken: ConnectionResetError(10054, 'An existing connection was forcibly closed by the remote host', None, 10054, None)", ConnectionResetError(10054, 'An existing connection was forcibly closed by the remote host', None, 10054, None))

During handling of the above exception, another exception occurred:

Traceback (most recent call last):
  File "C:\Users\Administrator\Desktop\instabot.py-master\instabot_py\instabot.py", line 1631, in get_media_id_recent_feed
    r = self.s.get(url_tag)
  File "C:\Users\Administrator\AppData\Local\Programs\Python\Python37-32\lib\site-packages\requests\sessions.py", line 546, in get
    return self.request('GET', url, **kwargs)
  File "C:\Users\Administrator\AppData\Local\Programs\Python\Python37-32\lib\site-packages\requests\sessions.py", line 533, in request
    resp = self.send(prep, **send_kwargs)
  File "C:\Users\Administrator\AppData\Local\Programs\Python\Python37-32\lib\site-packages\requests\sessions.py", line 686, in send
    r.content
  File "C:\Users\Administrator\AppData\Local\Programs\Python\Python37-32\lib\site-packages\requests\models.py", line 828, in content
    self._content = b''.join(self.iter_content(CONTENT_CHUNK_SIZE)) or b''
  File "C:\Users\Administrator\AppData\Local\Programs\Python\Python37-32\lib\site-packages\requests\models.py", line 753, in generate
    raise ChunkedEncodingError(e)
requests.exceptions.ChunkedEncodingError: ("Connection broken: ConnectionResetError(10054, 'An existing connection was forcibly closed by the remote host', None, 10054, None)", ConnectionResetError(10054, 'An existing connection was forcibly closed by the remote host', None, 10054, None))
ERROR:root:get_media_id_by_tag
Traceback (most recent call last):
  File "C:\Users\Administrator\AppData\Local\Programs\Python\Python37-32\lib\site-packages\urllib3\response.py", line 360, in _error_catcher
    yield
  File "C:\Users\Administrator\AppData\Local\Programs\Python\Python37-32\lib\site-packages\urllib3\response.py", line 442, in read
    data = self._fp.read(amt)
  File "C:\Users\Administrator\AppData\Local\Programs\Python\Python37-32\lib\http\client.py", line 447, in read
    n = self.readinto(b)
  File "C:\Users\Administrator\AppData\Local\Programs\Python\Python37-32\lib\http\client.py", line 491, in readinto
    n = self.fp.readinto(b)
  File "C:\Users\Administrator\AppData\Local\Programs\Python\Python37-32\lib\socket.py", line 589, in readinto
    return self._sock.recv_into(b)
  File "C:\Users\Administrator\AppData\Local\Programs\Python\Python37-32\lib\ssl.py", line 1052, in recv_into
    return self.read(nbytes, buffer)
  File "C:\Users\Administrator\AppData\Local\Programs\Python\Python37-32\lib\ssl.py", line 911, in read
    return self._sslobj.read(len, buffer)
ConnectionResetError: [WinError 10054] An existing connection was forcibly closed by the remote host

During handling of the above exception, another exception occurred:

Traceback (most recent call last):
  File "C:\Users\Administrator\AppData\Local\Programs\Python\Python37-32\lib\site-packages\requests\models.py", line 750, in generate
    for chunk in self.raw.stream(chunk_size, decode_content=True):
  File "C:\Users\Administrator\AppData\Local\Programs\Python\Python37-32\lib\site-packages\urllib3\response.py", line 494, in stream
    data = self.read(amt=amt, decode_content=decode_content)
  File "C:\Users\Administrator\AppData\Local\Programs\Python\Python37-32\lib\site-packages\urllib3\response.py", line 459, in read
    raise IncompleteRead(self._fp_bytes_read, self.length_remaining)
  File "C:\Users\Administrator\AppData\Local\Programs\Python\Python37-32\lib\contextlib.py", line 130, in __exit__
    self.gen.throw(type, value, traceback)
  File "C:\Users\Administrator\AppData\Local\Programs\Python\Python37-32\lib\site-packages\urllib3\response.py", line 378, in _error_catcher
    raise ProtocolError('Connection broken: %r' % e, e)
urllib3.exceptions.ProtocolError: ("Connection broken: ConnectionResetError(10054, 'An existing connection was forcibly closed by the remote host', None, 10054, None)", ConnectionResetError(10054, 'An existing connection was forcibly closed by the remote host', None, 10054, None))

During handling of the above exception, another exception occurred:

Traceback (most recent call last):
  File "C:\Users\Administrator\Desktop\instabot.py-master\instabot_py\instabot.py", line 685, in get_media_id_by_tag
    r = self.s.get(url_tag)
  File "C:\Users\Administrator\AppData\Local\Programs\Python\Python37-32\lib\site-packages\requests\sessions.py", line 546, in get
    return self.request('GET', url, **kwargs)
  File "C:\Users\Administrator\AppData\Local\Programs\Python\Python37-32\lib\site-packages\requests\sessions.py", line 533, in request
    resp = self.send(prep, **send_kwargs)
  File "C:\Users\Administrator\AppData\Local\Programs\Python\Python37-32\lib\site-packages\requests\sessions.py", line 686, in send
    r.content
  File "C:\Users\Administrator\AppData\Local\Programs\Python\Python37-32\lib\site-packages\requests\models.py", line 828, in content
    self._content = b''.join(self.iter_content(CONTENT_CHUNK_SIZE)) or b''
  File "C:\Users\Administrator\AppData\Local\Programs\Python\Python37-32\lib\site-packages\requests\models.py", line 753, in generate
    raise ChunkedEncodingError(e)
requests.exceptions.ChunkedEncodingError: ("Connection broken: ConnectionResetError(10054, 'An existing connection was forcibly closed by the remote host', None, 10054, None)", ConnectionResetError(10054, 'An existing connection was forcibly closed by the remote host', None, 10054, None))
ERROR:root:get_media_id_by_tag
Traceback (most recent call last):
  File "C:\Users\Administrator\AppData\Local\Programs\Python\Python37-32\lib\site-packages\urllib3\connectionpool.py", line 600, in urlopen
    chunked=chunked)
  File "C:\Users\Administrator\AppData\Local\Programs\Python\Python37-32\lib\site-packages\urllib3\connectionpool.py", line 384, in _make_request
    six.raise_from(e, None)
  File "<string>", line 2, in raise_from
  File "C:\Users\Administrator\AppData\Local\Programs\Python\Python37-32\lib\site-packages\urllib3\connectionpool.py", line 380, in _make_request
    httplib_response = conn.getresponse()
  File "C:\Users\Administrator\AppData\Local\Programs\Python\Python37-32\lib\http\client.py", line 1321, in getresponse
    response.begin()
  File "C:\Users\Administrator\AppData\Local\Programs\Python\Python37-32\lib\http\client.py", line 320, in begin
    self.headers = self.msg = parse_headers(self.fp)
  File "C:\Users\Administrator\AppData\Local\Programs\Python\Python37-32\lib\http\client.py", line 205, in parse_headers
    line = fp.readline(_MAXLINE + 1)
  File "C:\Users\Administrator\AppData\Local\Programs\Python\Python37-32\lib\socket.py", line 589, in readinto
    return self._sock.recv_into(b)
  File "C:\Users\Administrator\AppData\Local\Programs\Python\Python37-32\lib\ssl.py", line 1052, in recv_into
    return self.read(nbytes, buffer)
  File "C:\Users\Administrator\AppData\Local\Programs\Python\Python37-32\lib\ssl.py", line 911, in read
    return self._sslobj.read(len, buffer)
ConnectionResetError: [WinError 10054] An existing connection was forcibly closed by the remote host

During handling of the above exception, another exception occurred:

Traceback (most recent call last):
  File "C:\Users\Administrator\AppData\Local\Programs\Python\Python37-32\lib\site-packages\requests\adapters.py", line 449, in send
    timeout=timeout
  File "C:\Users\Administrator\AppData\Local\Programs\Python\Python37-32\lib\site-packages\urllib3\connectionpool.py", line 638, in urlopen
    _stacktrace=sys.exc_info()[2])
  File "C:\Users\Administrator\AppData\Local\Programs\Python\Python37-32\lib\site-packages\urllib3\util\retry.py", line 367, in increment
    raise six.reraise(type(error), error, _stacktrace)
  File "C:\Users\Administrator\AppData\Local\Programs\Python\Python37-32\lib\site-packages\urllib3\packages\six.py", line 685, in reraise
    raise value.with_traceback(tb)
  File "C:\Users\Administrator\AppData\Local\Programs\Python\Python37-32\lib\site-packages\urllib3\connectionpool.py", line 600, in urlopen
    chunked=chunked)
  File "C:\Users\Administrator\AppData\Local\Programs\Python\Python37-32\lib\site-packages\urllib3\connectionpool.py", line 384, in _make_request
    six.raise_from(e, None)
  File "<string>", line 2, in raise_from
  File "C:\Users\Administrator\AppData\Local\Programs\Python\Python37-32\lib\site-packages\urllib3\connectionpool.py", line 380, in _make_request
    httplib_response = conn.getresponse()
  File "C:\Users\Administrator\AppData\Local\Programs\Python\Python37-32\lib\http\client.py", line 1321, in getresponse
    response.begin()
  File "C:\Users\Administrator\AppData\Local\Programs\Python\Python37-32\lib\http\client.py", line 320, in begin
    self.headers = self.msg = parse_headers(self.fp)
  File "C:\Users\Administrator\AppData\Local\Programs\Python\Python37-32\lib\http\client.py", line 205, in parse_headers
    line = fp.readline(_MAXLINE + 1)
  File "C:\Users\Administrator\AppData\Local\Programs\Python\Python37-32\lib\socket.py", line 589, in readinto
    return self._sock.recv_into(b)
  File "C:\Users\Administrator\AppData\Local\Programs\Python\Python37-32\lib\ssl.py", line 1052, in recv_into
    return self.read(nbytes, buffer)
  File "C:\Users\Administrator\AppData\Local\Programs\Python\Python37-32\lib\ssl.py", line 911, in read
    return self._sslobj.read(len, buffer)
urllib3.exceptions.ProtocolError: ('Connection aborted.', ConnectionResetError(10054, 'An existing connection was forcibly closed by the remote host', None, 10054, None))

During handling of the above exception, another exception occurred:

Traceback (most recent call last):
  File "C:\Users\Administrator\Desktop\instabot.py-master\instabot_py\instabot.py", line 685, in get_media_id_by_tag
    r = self.s.get(url_tag)
  File "C:\Users\Administrator\AppData\Local\Programs\Python\Python37-32\lib\site-packages\requests\sessions.py", line 546, in get
    return self.request('GET', url, **kwargs)
  File "C:\Users\Administrator\AppData\Local\Programs\Python\Python37-32\lib\site-packages\requests\sessions.py", line 533, in request
    resp = self.send(prep, **send_kwargs)
  File "C:\Users\Administrator\AppData\Local\Programs\Python\Python37-32\lib\site-packages\requests\sessions.py", line 646, in send
    r = adapter.send(request, **kwargs)
  File "C:\Users\Administrator\AppData\Local\Programs\Python\Python37-32\lib\site-packages\requests\adapters.py", line 498, in send
    raise ConnectionError(err, request=request)
requests.exceptions.ConnectionError: ('Connection aborted.', ConnectionResetError(10054, 'An existing connection was forcibly closed by the remote host', None, 10054, None))
ERROR:root:Except on auto_unfollow!
Traceback (most recent call last):
  File "C:\Users\Administrator\Desktop\instabot.py-master\instabot_py\instabot.py", line 1412, in auto_unfollow
    "window._sharedData = (.*?);</script>", r.text, re.DOTALL
AttributeError: 'NoneType' object has no attribute 'group'
